<?xml version="1.0"?>
<robot name="custom_rover">
  
  <!-- Base Link -->
  <link name="base_link">
    <visual>
      <origin xyz="0 0 0" rpy="0 0 0"/>
      <geometry>
        <mesh filename="file:///home/darshan/lunar/src/lunabot_simulation/models/custom_rover/meshes/rover.obj" scale="1 1 1"/>
      </geometry>
      <material name="rover_material">
        <color rgba="0.8 0.8 0.9 1"/>
      </material>
    </visual>
    
    <collision>
      <origin xyz="0 0 0" rpy="0 0 0"/>
      <geometry>
        <mesh filename="file:///home/darshan/lunar/src/lunabot_simulation/models/custom_rover/meshes/rover.obj" scale="1 1 1"/>
      </geometry>
    </collision>
    
    <inertial>
      <origin xyz="0 0 0" rpy="0 0 0"/>
      <mass value="50"/>
      <inertia ixx="4.0" ixy="0" ixz="0" iyy="8.0" iyz="0" izz="10.0"/>
    </inertial>
  </link>
  
  <!-- Left Wheel -->
  <link name="left_wheel">
    <visual>
      <origin xyz="0 0 0" rpy="1.5708 0 0"/>
      <geometry>
        <cylinder radius="0.2" length="0.1"/>
      </geometry>
      <material name="wheel_material">
        <color rgba="0.3 0.3 0.3 1"/>
      </material>
    </visual>
    
    <collision>
      <origin xyz="0 0 0" rpy="1.5708 0 0"/>
      <geometry>
        <cylinder radius="0.2" length="0.1"/>
      </geometry>
    </collision>
    
    <inertial>
      <origin xyz="0 0 0" rpy="1.5708 0 0"/>
      <mass value="5"/>
      <inertia ixx="0.1" ixy="0" ixz="0" iyy="0.1" iyz="0" izz="0.1"/>
    </inertial>
  </link>
  
  <!-- Right Wheel -->
  <link name="right_wheel">
    <visual>
      <origin xyz="0 0 0" rpy="1.5708 0 0"/>
      <geometry>
        <cylinder radius="0.2" length="0.1"/>
      </geometry>
      <material name="wheel_material">
        <color rgba="0.3 0.3 0.3 1"/>
      </material>
    </visual>
    
    <collision>
      <origin xyz="0 0 0" rpy="1.5708 0 0"/>
      <geometry>
        <cylinder radius="0.2" length="0.1"/>
      </geometry>
    </collision>
    
    <inertial>
      <origin xyz="0 0 0" rpy="1.5708 0 0"/>
      <mass value="5"/>
      <inertia ixx="0.1" ixy="0" ixz="0" iyy="0.1" iyz="0" izz="0.1"/>
    </inertial>
  </link>
  
  <!-- Wheel Joints -->
  <joint name="left_wheel_joint" type="continuous">
    <parent link="base_link"/>
    <child link="left_wheel"/>
    <origin xyz="0 0.25 0" rpy="0 0 0"/>
    <axis xyz="0 1 0"/>
  </joint>
  
  <joint name="right_wheel_joint" type="continuous">
    <parent link="base_link"/>
    <child link="right_wheel"/>
    <origin xyz="0 -0.25 0" rpy="0 0 0"/>
    <axis xyz="0 1 0"/>
  </joint>
  
  <!-- Gazebo Plugins -->
  <gazebo>
    <plugin name="differential_drive_controller" filename="libgazebo_ros_diff_drive.so">
      <update_rate>30</update_rate>
      <left_joint>left_wheel_joint</left_joint>
      <right_joint>right_wheel_joint</right_joint>
      <wheel_separation>0.5</wheel_separation>
      <wheel_diameter>0.4</wheel_diameter>
      <max_wheel_torque>200</max_wheel_torque>
      <max_wheel_acceleration>10.0</max_wheel_acceleration>
      <command_topic>cmd_vel</command_topic>
      <publish_odom>true</publish_odom>
      <publish_odom_tf>true</publish_odom_tf>
      <publish_wheel_tf>true</publish_wheel_tf>
      <odometry_topic>odom</odometry_topic>
      <odometry_frame>odom</odometry_frame>
      <robot_base_frame>base_link</robot_base_frame>
    </plugin>
  </gazebo>
  
</robot>