<?xml version="1.0"?>
<robot name="nasa_realistic_rover" xmlns:xacro="http://www.ros.org/wiki/xacro">
  
  <!-- Main Rover Body (NASA Perseverance style) -->
  <link name="base_link">
    <visual>
      <geometry>
        <box size="3.0 2.5 1.2"/>
      </geometry>
      <material name="rover_white">
        <color rgba="0.95 0.95 0.95 1"/>
      </material>
    </visual>
    <collision>
      <geometry>
        <box size="3.0 2.5 1.2"/>
      </geometry>
    </collision>
    <inertial>
      <mass value="899"/>  <!-- NASA Perseverance mass -->
      <inertia ixx="150" ixy="0" ixz="0" iyy="200" iyz="0" izz="250"/>
    </inertial>
  </link>

  <!-- 6-Wheel Rocker-Bogie Suspension System -->
  
  <!-- Front Left Wheel -->
  <link name="front_left_wheel">
    <visual>
      <geometry>
        <cylinder radius="0.525" length="0.4"/>  <!-- Larger wheels like real NASA rover -->
      </geometry>
      <material name="wheel_titanium">
        <color rgba="0.4 0.4 0.45 1"/>
      </material>
    </visual>
    <collision>
      <geometry>
        <cylinder radius="0.525" length="0.4"/>
      </geometry>
    </collision>
    <inertial>
      <mass value="25"/>
      <inertia ixx="3.45" ixy="0" ixz="0" iyy="3.45" iyz="0" izz="6.9"/>
    </inertial>
  </link>

  <!-- Front Right Wheel -->
  <link name="front_right_wheel">
    <visual>
      <geometry>
        <cylinder radius="0.525" length="0.4"/>
      </geometry>
      <material name="wheel_titanium">
        <color rgba="0.4 0.4 0.45 1"/>
      </material>
    </visual>
    <collision>
      <geometry>
        <cylinder radius="0.525" length="0.4"/>
      </geometry>
    </collision>
    <inertial>
      <mass value="25"/>
      <inertia ixx="3.45" ixy="0" ixz="0" iyy="3.45" iyz="0" izz="6.9"/>
    </inertial>
  </link>

  <!-- Middle Left Wheel -->
  <link name="middle_left_wheel">
    <visual>
      <geometry>
        <cylinder radius="0.525" length="0.4"/>
      </geometry>
      <material name="wheel_titanium">
        <color rgba="0.4 0.4 0.45 1"/>
      </material>
    </visual>
    <collision>
      <geometry>
        <cylinder radius="0.525" length="0.4"/>
      </geometry>
    </collision>
    <inertial>
      <mass value="25"/>
      <inertia ixx="3.45" ixy="0" ixz="0" iyy="3.45" iyz="0" izz="6.9"/>
    </inertial>
  </link>

  <!-- Middle Right Wheel -->
  <link name="middle_right_wheel">
    <visual>
      <geometry>
        <cylinder radius="0.525" length="0.4"/>
      </geometry>
      <material name="wheel_titanium">
        <color rgba="0.4 0.4 0.45 1"/>
      </material>
    </visual>
    <collision>
      <geometry>
        <cylinder radius="0.525" length="0.4"/>
      </geometry>
    </collision>
    <inertial>
      <mass value="25"/>
      <inertia ixx="3.45" ixy="0" ixz="0" iyy="3.45" iyz="0" izz="6.9"/>
    </inertial>
  </link>

  <!-- Rear Left Wheel -->
  <link name="rear_left_wheel">
    <visual>
      <geometry>
        <cylinder radius="0.525" length="0.4"/>
      </geometry>
      <material name="wheel_titanium">
        <color rgba="0.4 0.4 0.45 1"/>
      </material>
    </visual>
    <collision>
      <geometry>
        <cylinder radius="0.525" length="0.4"/>
      </geometry>
    </collision>
    <inertial>
      <mass value="25"/>
      <inertia ixx="3.45" ixy="0" ixz="0" iyy="3.45" iyz="0" izz="6.9"/>
    </inertial>
  </link>

  <!-- Rear Right Wheel -->
  <link name="rear_right_wheel">
    <visual>
      <geometry>
        <cylinder radius="0.525" length="0.4"/>
      </geometry>
      <material name="wheel_titanium">
        <color rgba="0.4 0.4 0.45 1"/>
      </material>
    </visual>
    <collision>
      <geometry>
        <cylinder radius="0.525" length="0.4"/>
      </geometry>
    </collision>
    <inertial>
      <mass value="25"/>
      <inertia ixx="3.45" ixy="0" ixz="0" iyy="3.45" iyz="0" izz="6.9"/>
    </inertial>
  </link>

  <!-- Wheel Joints (6-wheel drive) -->
  <joint name="front_left_wheel_joint" type="continuous">
    <parent link="base_link"/>
    <child link="front_left_wheel"/>
    <origin xyz="1.2 1.4 -0.6" rpy="-1.5707 0 0"/>
    <axis xyz="0 0 1"/>
  </joint>

  <joint name="front_right_wheel_joint" type="continuous">
    <parent link="base_link"/>
    <child link="front_right_wheel"/>
    <origin xyz="1.2 -1.4 -0.6" rpy="-1.5707 0 0"/>
    <axis xyz="0 0 1"/>
  </joint>

  <joint name="middle_left_wheel_joint" type="continuous">
    <parent link="base_link"/>
    <child link="middle_left_wheel"/>
    <origin xyz="0 1.4 -0.6" rpy="-1.5707 0 0"/>
    <axis xyz="0 0 1"/>
  </joint>

  <joint name="middle_right_wheel_joint" type="continuous">
    <parent link="base_link"/>
    <child link="middle_right_wheel"/>
    <origin xyz="0 -1.4 -0.6" rpy="-1.5707 0 0"/>
    <axis xyz="0 0 1"/>
  </joint>

  <joint name="rear_left_wheel_joint" type="continuous">
    <parent link="base_link"/>
    <child link="rear_left_wheel"/>
    <origin xyz="-1.2 1.4 -0.6" rpy="-1.5707 0 0"/>
    <axis xyz="0 0 1"/>
  </joint>

  <joint name="rear_right_wheel_joint" type="continuous">
    <parent link="base_link"/>
    <child link="rear_right_wheel"/>
    <origin xyz="-1.2 -1.4 -0.6" rpy="-1.5707 0 0"/>
    <axis xyz="0 0 1"/>
  </joint>

  <!-- Robotic Arm (NASA style) -->
  <link name="robotic_arm">
    <visual>
      <geometry>
        <cylinder radius="0.08" length="2.2"/>
      </geometry>
      <material name="arm_silver">
        <color rgba="0.7 0.7 0.75 1"/>
      </material>
    </visual>
    <collision>
      <geometry>
        <cylinder radius="0.08" length="2.2"/>
      </geometry>
    </collision>
    <inertial>
      <mass value="30"/>
      <inertia ixx="12.1" ixy="0" ixz="0" iyy="12.1" iyz="0" izz="0.096"/>
    </inertial>
  </link>

  <joint name="arm_joint" type="revolute">
    <parent link="base_link"/>
    <child link="robotic_arm"/>
    <origin xyz="-0.8 0 0.8" rpy="0 0.5 0"/>
    <axis xyz="0 1 0"/>
    <limit lower="-1.57" upper="1.57" effort="100" velocity="0.5"/>
  </joint>

  <!-- Scientific Instrument Mast (like Perseverance) -->
  <link name="science_mast">
    <visual>
      <geometry>
        <cylinder radius="0.12" length="1.8"/>
      </geometry>
      <material name="mast_black">
        <color rgba="0.2 0.2 0.25 1"/>
      </material>
    </visual>
    <collision>
      <geometry>
        <cylinder radius="0.12" length="1.8"/>
      </geometry>
    </collision>
    <inertial>
      <mass value="15"/>
      <inertia ixx="4.1" ixy="0" ixz="0" iyy="4.1" iyz="0" izz="0.108"/>
    </inertial>
  </link>

  <joint name="mast_joint" type="fixed">
    <parent link="base_link"/>
    <child link="science_mast"/>
    <origin xyz="0.8 0 1.5" rpy="0 0 0"/>
  </joint>

  <!-- High-Gain Antenna (Communication with Earth) -->
  <link name="high_gain_antenna">
    <visual>
      <geometry>
        <cylinder radius="0.6" length="0.15"/>
      </geometry>
      <material name="antenna_gold">
        <color rgba="0.8 0.65 0.2 1"/>
      </material>
    </visual>
    <collision>
      <geometry>
        <cylinder radius="0.6" length="0.15"/>
      </geometry>
    </collision>
    <inertial>
      <mass value="8"/>
      <inertia ixx="1.44" ixy="0" ixz="0" iyy="1.44" iyz="0" izz="1.44"/>
    </inertial>
  </link>

  <joint name="antenna_joint" type="revolute">
    <parent link="base_link"/>
    <child link="high_gain_antenna"/>
    <origin xyz="-1.2 0 1.0" rpy="0 0.3 0"/>
    <axis xyz="0 0 1"/>
    <limit lower="-3.14" upper="3.14" effort="50" velocity="1.0"/>
  </joint>

  <!-- LiDAR Scanner (on mast) -->
  <link name="lidar_link">
    <visual>
      <geometry>
        <cylinder radius="0.15" length="0.2"/>
      </geometry>
      <material name="lidar_black">
        <color rgba="0.1 0.1 0.15 1"/>
      </material>
    </visual>
    <collision>
      <geometry>
        <cylinder radius="0.15" length="0.2"/>
      </geometry>
    </collision>
    <inertial>
      <mass value="5"/>
      <inertia ixx="0.053" ixy="0" ixz="0" iyy="0.053" iyz="0" izz="0.056"/>
    </inertial>
  </link>

  <joint name="lidar_joint" type="fixed">
    <parent link="science_mast"/>
    <child link="lidar_link"/>
    <origin xyz="0 0 0.9" rpy="0 0 0"/>
  </joint>

  <!-- Stereo Navigation Cameras -->
  <link name="navcam_link">
    <visual>
      <geometry>
        <box size="0.3 0.8 0.15"/>
      </geometry>
      <material name="camera_black">
        <color rgba="0.15 0.15 0.2 1"/>
      </material>
    </visual>
    <collision>
      <geometry>
        <box size="0.3 0.8 0.15"/>
      </geometry>
    </collision>
    <inertial>
      <mass value="3"/>
      <inertia ixx="0.16" ixy="0" ixz="0" iyy="0.023" iyz="0" izz="0.17"/>
    </inertial>
  </link>

  <joint name="navcam_joint" type="fixed">
    <parent link="science_mast"/>
    <child link="navcam_link"/>
    <origin xyz="0 0 0.6" rpy="0 0 0"/>
  </joint>

  <!-- Solar Panels (deployable) -->
  <link name="solar_panel_left">
    <visual>
      <geometry>
        <box size="0.08 2.0 3.5"/>
      </geometry>
      <material name="solar_blue">
        <color rgba="0.1 0.2 0.6 1"/>
      </material>
    </visual>
    <collision>
      <geometry>
        <box size="0.08 2.0 3.5"/>
      </geometry>
    </collision>
    <inertial>
      <mass value="18"/>
      <inertia ixx="18.4" ixy="0" ixz="0" iyy="18.4" iyz="0" izz="6.0"/>
    </inertial>
  </link>

  <joint name="solar_left_joint" type="revolute">
    <parent link="base_link"/>
    <child link="solar_panel_left"/>
    <origin xyz="0 2.0 1.0" rpy="0 0.1 0"/>
    <axis xyz="1 0 0"/>
    <limit lower="-0.5" upper="0.5" effort="20" velocity="0.2"/>
  </joint>

  <link name="solar_panel_right">
    <visual>
      <geometry>
        <box size="0.08 2.0 3.5"/>
      </geometry>
      <material name="solar_blue">
        <color rgba="0.1 0.2 0.6 1"/>
      </material>
    </visual>
    <collision>
      <geometry>
        <box size="0.08 2.0 3.5"/>
      </geometry>
    </collision>
    <inertial>
      <mass value="18"/>
      <inertia ixx="18.4" ixy="0" ixz="0" iyy="18.4" iyz="0" izz="6.0"/>
    </inertial>
  </link>

  <joint name="solar_right_joint" type="revolute">
    <parent link="base_link"/>
    <child link="solar_panel_right"/>
    <origin xyz="0 -2.0 1.0" rpy="0 0.1 0"/>
    <axis xyz="1 0 0"/>
    <limit lower="-0.5" upper="0.5" effort="20" velocity="0.2"/>
  </joint>

  <!-- RTG Power Source (NASA style nuclear battery) -->
  <link name="rtg_power">
    <visual>
      <geometry>
        <cylinder radius="0.4" length="0.8"/>
      </geometry>
      <material name="rtg_silver">
        <color rgba="0.75 0.75 0.8 1"/>
      </material>
    </visual>
    <collision>
      <geometry>
        <cylinder radius="0.4" length="0.8"/>
      </geometry>
    </collision>
    <inertial>
      <mass value="45"/>
      <inertia ixx="2.4" ixy="0" ixz="0" iyy="2.4" iyz="0" izz="3.6"/>
    </inertial>
  </link>

  <joint name="rtg_joint" type="fixed">
    <parent link="base_link"/>
    <child link="rtg_power"/>
    <origin xyz="-1.4 0 0.2" rpy="1.5707 0 0"/>
  </joint>

  <!-- Gazebo Plugins for 6-wheel drive -->
  <gazebo>
    <plugin name="diff_drive_controller" filename="libgazebo_ros_diff_drive.so">
      <ros>
        <namespace>/nasa_rover</namespace>
      </ros>
      <left_joint>front_left_wheel_joint</left_joint>
      <right_joint>front_right_wheel_joint</right_joint>
      <left_joint>middle_left_wheel_joint</left_joint>
      <right_joint>middle_right_wheel_joint</right_joint>
      <left_joint>rear_left_wheel_joint</left_joint>
      <right_joint>rear_right_wheel_joint</right_joint>
      <wheel_separation>2.8</wheel_separation>
      <wheel_diameter>1.05</wheel_diameter>
      <max_wheel_torque>200</max_wheel_torque>
      <max_wheel_acceleration>3.0</max_wheel_acceleration>
      <publish_odom>true</publish_odom>
      <publish_odom_tf>true</publish_odom_tf>
      <publish_wheel_tf>true</publish_wheel_tf>
      <odometry_frame>odom</odometry_frame>
      <robot_base_frame>base_link</robot_base_frame>
    </plugin>
  </gazebo>

  <!-- LiDAR Plugin -->
  <gazebo reference="lidar_link">
    <plugin name="lidar_controller" filename="libgazebo_ros_ray_sensor.so">
      <ros>
        <namespace>/nasa_rover</namespace>
        <remapping>~/out:=scan</remapping>
      </ros>
      <output_type>sensor_msgs/LaserScan</output_type>
      <frame_name>lidar_link</frame_name>
      <update_rate>10</update_rate>
      <ray>
        <scan>
          <horizontal>
            <samples>720</samples>  <!-- High resolution like real NASA LiDAR -->
            <resolution>1</resolution>
            <min_angle>-3.14159</min_angle>
            <max_angle>3.14159</max_angle>
          </horizontal>
        </scan>
        <range>
          <min>0.3</min>
          <max>100.0</max>  <!-- Long range like real rover -->
          <resolution>0.01</resolution>
        </range>
      </ray>
    </plugin>
  </gazebo>

  <!-- Navigation Camera Plugin -->
  <gazebo reference="navcam_link">
    <plugin name="camera_controller" filename="libgazebo_ros_camera.so">
      <ros>
        <namespace>/nasa_rover</namespace>
        <remapping>image_raw:=camera/image_raw</remapping>
        <remapping>camera_info:=camera/camera_info</remapping>
      </ros>
      <camera_name>navigation_camera</camera_name>
      <frame_name>navcam_link</frame_name>
      <update_rate>10</update_rate>
      <image>
        <width>1600</width>  <!-- High resolution like NASA -->
        <height>1200</height>
        <format>R8G8B8</format>
      </image>
      <clip>
        <near>0.1</near>
        <far>1000</far>
      </clip>
    </plugin>
  </gazebo>

</robot>
