<?xml version="1.0"?>
<robot name="nasa_lunar_rover" xmlns:xacro="http://www.ros.org/wiki/xacro">
  
  <!-- Main Rover Chassis -->
  <link name="base_link">
    <visual>
      <geometry>
        <box size="3.0 2.0 1.0"/>
      </geometry>
      <material name="rover_white">
        <color rgba="0.9 0.9 0.9 1"/>
      </material>
    </visual>
    <collision>
      <geometry>
        <box size="3.0 2.0 1.0"/>
      </geometry>
    </collision>
    <inertial>
      <mass value="400"/>
      <inertia ixx="40" ixy="0" ixz="0" iyy="60" iyz="0" izz="80"/>
    </inertial>
  </link>

  <!-- Front Left Wheel -->
  <link name="front_left_wheel">
    <visual>
      <geometry>
        <cylinder radius="0.4" length="0.3"/>
      </geometry>
      <material name="wheel_gray">
        <color rgba="0.3 0.3 0.3 1"/>
      </material>
    </visual>
    <collision>
      <geometry>
        <cylinder radius="0.4" length="0.3"/>
      </geometry>
    </collision>
    <inertial>
      <mass value="15"/>
      <inertia ixx="1.2" ixy="0" ixz="0" iyy="1.2" iyz="0" izz="2.4"/>
    </inertial>
  </link>

  <!-- Front Right Wheel -->
  <link name="front_right_wheel">
    <visual>
      <geometry>
        <cylinder radius="0.4" length="0.3"/>
      </geometry>
      <material name="wheel_gray">
        <color rgba="0.3 0.3 0.3 1"/>
      </material>
    </visual>
    <collision>
      <geometry>
        <cylinder radius="0.4" length="0.3"/>
      </geometry>
    </collision>
    <inertial>
      <mass value="15"/>
      <inertia ixx="1.2" ixy="0" ixz="0" iyy="1.2" iyz="0" izz="2.4"/>
    </inertial>
  </link>

  <!-- Rear Left Wheel -->
  <link name="rear_left_wheel">
    <visual>
      <geometry>
        <cylinder radius="0.4" length="0.3"/>
      </geometry>
      <material name="wheel_gray">
        <color rgba="0.3 0.3 0.3 1"/>
      </material>
    </visual>
    <collision>
      <geometry>
        <cylinder radius="0.4" length="0.3"/>
      </geometry>
    </collision>
    <inertial>
      <mass value="15"/>
      <inertia ixx="1.2" ixy="0" ixz="0" iyy="1.2" iyz="0" izz="2.4"/>
    </inertial>
  </link>

  <!-- Rear Right Wheel -->
  <link name="rear_right_wheel">
    <visual>
      <geometry>
        <cylinder radius="0.4" length="0.3"/>
      </geometry>
      <material name="wheel_gray">
        <color rgba="0.3 0.3 0.3 1"/>
      </material>
    </visual>
    <collision>
      <geometry>
        <cylinder radius="0.4" length="0.3"/>
      </geometry>
    </collision>
    <inertial>
      <mass value="15"/>
      <inertia ixx="1.2" ixy="0" ixz="0" iyy="1.2" iyz="0" izz="2.4"/>
    </inertial>
  </link>

  <!-- Wheel Joints -->
  <joint name="front_left_wheel_joint" type="continuous">
    <parent link="base_link"/>
    <child link="front_left_wheel"/>
    <origin xyz="1.2 1.2 -0.5" rpy="-1.5707 0 0"/>
    <axis xyz="0 0 1"/>
  </joint>

  <joint name="front_right_wheel_joint" type="continuous">
    <parent link="base_link"/>
    <child link="front_right_wheel"/>
    <origin xyz="1.2 -1.2 -0.5" rpy="-1.5707 0 0"/>
    <axis xyz="0 0 1"/>
  </joint>

  <joint name="rear_left_wheel_joint" type="continuous">
    <parent link="base_link"/>
    <child link="rear_left_wheel"/>
    <origin xyz="-1.2 1.2 -0.5" rpy="-1.5707 0 0"/>
    <axis xyz="0 0 1"/>
  </joint>

  <joint name="rear_right_wheel_joint" type="continuous">
    <parent link="base_link"/>
    <child link="rear_right_wheel"/>
    <origin xyz="-1.2 -1.2 -0.5" rpy="-1.5707 0 0"/>
    <axis xyz="0 0 1"/>
  </joint>

  <!-- Communication Dish -->
  <link name="comm_dish">
    <visual>
      <geometry>
        <sphere radius="0.6"/>
      </geometry>
      <material name="dish_gold">
        <color rgba="0.8 0.6 0.2 1"/>
      </material>
    </visual>
    <collision>
      <geometry>
        <sphere radius="0.6"/>
      </geometry>
    </collision>
    <inertial>
      <mass value="5"/>
      <inertia ixx="0.72" ixy="0" ixz="0" iyy="0.72" iyz="0" izz="0.72"/>
    </inertial>
  </link>

  <joint name="comm_dish_joint" type="fixed">
    <parent link="base_link"/>
    <child link="comm_dish"/>
    <origin xyz="-0.5 0 1.2" rpy="0 0.3 0"/>
  </joint>

  <!-- Scientific Instruments Mast -->
  <link name="instrument_mast">
    <visual>
      <geometry>
        <cylinder radius="0.1" length="2.0"/>
      </geometry>
      <material name="mast_silver">
        <color rgba="0.7 0.7 0.7 1"/>
      </material>
    </visual>
    <collision>
      <geometry>
        <cylinder radius="0.1" length="2.0"/>
      </geometry>
    </collision>
    <inertial>
      <mass value="8"/>
      <inertia ixx="2.67" ixy="0" ixz="0" iyy="2.67" iyz="0" izz="0.04"/>
    </inertial>
  </link>

  <joint name="instrument_mast_joint" type="fixed">
    <parent link="base_link"/>
    <child link="instrument_mast"/>
    <origin xyz="0.8 0 1.5" rpy="0 0 0"/>
  </joint>

  <!-- LiDAR Scanner -->
  <link name="lidar_link">
    <visual>
      <geometry>
        <cylinder radius="0.2" length="0.3"/>
      </geometry>
      <material name="lidar_black">
        <color rgba="0.1 0.1 0.1 1"/>
      </material>
    </visual>
    <collision>
      <geometry>
        <cylinder radius="0.2" length="0.3"/>
      </geometry>
    </collision>
    <inertial>
      <mass value="3"/>
      <inertia ixx="0.045" ixy="0" ixz="0" iyy="0.045" iyz="0" izz="0.06"/>
    </inertial>
  </link>

  <joint name="lidar_joint" type="fixed">
    <parent link="instrument_mast"/>
    <child link="lidar_link"/>
    <origin xyz="0 0 1.0" rpy="0 0 0"/>
  </joint>

  <!-- Stereo Camera System -->
  <link name="camera_link">
    <visual>
      <geometry>
        <box size="0.3 0.6 0.2"/>
      </geometry>
      <material name="camera_black">
        <color rgba="0.2 0.2 0.2 1"/>
      </material>
    </visual>
    <collision>
      <geometry>
        <box size="0.3 0.6 0.2"/>
      </geometry>
    </collision>
    <inertial>
      <mass value="2"/>
      <inertia ixx="0.067" ixy="0" ixz="0" iyy="0.027" iyz="0" izz="0.083"/>
    </inertial>
  </link>

  <joint name="camera_joint" type="fixed">
    <parent link="instrument_mast"/>
    <child link="camera_link"/>
    <origin xyz="0 0 0.5" rpy="0 0 0"/>
  </joint>

  <!-- Solar Panels -->
  <link name="solar_panel_left">
    <visual>
      <geometry>
        <box size="0.1 1.5 2.0"/>
      </geometry>
      <material name="solar_blue">
        <color rgba="0.1 0.2 0.6 1"/>
      </material>
    </visual>
    <collision>
      <geometry>
        <box size="0.1 1.5 2.0"/>
      </geometry>
    </collision>
    <inertial>
      <mass value="10"/>
      <inertia ixx="5.83" ixy="0" ixz="0" iyy="3.35" iyz="0" izz="2.51"/>
    </inertial>
  </link>

  <joint name="solar_panel_left_joint" type="fixed">
    <parent link="base_link"/>
    <child link="solar_panel_left"/>
    <origin xyz="0 1.8 0.5" rpy="0 0.2 0"/>
  </joint>

  <link name="solar_panel_right">
    <visual>
      <geometry>
        <box size="0.1 1.5 2.0"/>
      </geometry>
      <material name="solar_blue">
        <color rgba="0.1 0.2 0.6 1"/>
      </material>
    </visual>
    <collision>
      <geometry>
        <box size="0.1 1.5 2.0"/>
      </geometry>
    </collision>
    <inertial>
      <mass value="10"/>
      <inertia ixx="5.83" ixy="0" ixz="0" iyy="3.35" iyz="0" izz="2.51"/>
    </inertial>
  </link>

  <joint name="solar_panel_right_joint" type="fixed">
    <parent link="base_link"/>
    <child link="solar_panel_right"/>
    <origin xyz="0 -1.8 0.5" rpy="0 0.2 0"/>
  </joint>

  <!-- Gazebo Plugins for 4-wheel drive -->
  <gazebo>
    <plugin name="skid_steer_drive_controller" filename="libgazebo_ros_diff_drive.so">
      <ros>
        <namespace>/nasa_lunar_rover</namespace>
      </ros>
      <left_joint>front_left_wheel_joint</left_joint>
      <right_joint>front_right_wheel_joint</right_joint>
      <left_joint>rear_left_wheel_joint</left_joint>
      <right_joint>rear_right_wheel_joint</right_joint>
      <wheel_separation>2.4</wheel_separation>
      <wheel_diameter>0.8</wheel_diameter>
      <max_wheel_torque>100</max_wheel_torque>
      <max_wheel_acceleration>2.0</max_wheel_acceleration>
      <publish_odom>true</publish_odom>
      <publish_odom_tf>true</publish_odom_tf>
      <publish_wheel_tf>true</publish_wheel_tf>
      <odometry_frame>odom</odometry_frame>
      <robot_base_frame>base_link</robot_base_frame>
    </plugin>
  </gazebo>

  <!-- LiDAR Plugin -->
  <gazebo reference="lidar_link">
    <plugin name="lidar_controller" filename="libgazebo_ros_ray_sensor.so">
      <ros>
        <namespace>/nasa_lunar_rover</namespace>
        <remapping>~/out:=scan</remapping>
      </ros>
      <output_type>sensor_msgs/LaserScan</output_type>
      <frame_name>lidar_link</frame_name>
      <update_rate>10</update_rate>
      <ray>
        <scan>
          <horizontal>
            <samples>360</samples>
            <resolution>1</resolution>
            <min_angle>-3.14159</min_angle>
            <max_angle>3.14159</max_angle>
          </horizontal>
        </scan>
        <range>
          <min>0.2</min>
          <max>50.0</max>
          <resolution>0.01</resolution>
        </range>
      </ray>
    </plugin>
  </gazebo>

  <!-- Camera Plugin -->
  <gazebo reference="camera_link">
    <plugin name="camera_controller" filename="libgazebo_ros_camera.so">
      <ros>
        <namespace>/nasa_lunar_rover</namespace>
        <remapping>image_raw:=camera/image_raw</remapping>
        <remapping>camera_info:=camera/camera_info</remapping>
      </ros>
      <camera_name>stereo_camera</camera_name>
      <frame_name>camera_link</frame_name>
      <update_rate>10</update_rate>
      <image>
        <width>1024</width>
        <height>768</height>
        <format>R8G8B8</format>
      </image>
      <clip>
        <near>0.1</near>
        <far>1000</far>
      </clip>
    </plugin>
  </gazebo>

</robot>
